Workbook

Sheet Start Here
D3: Learn CFD one cell at a time
D4: CFD by Hand
D5: FVM Foundations: free sample
D6: The first five worksheets of FVM Foundations, free. Start from zero and finish with your first finite volume solution and every kind of boundary cell.
B11: How this pack works
B13: 1 | C13: Read the How to Use tab first (two minutes, one Excel setting), then start with Lesson 0: the method and the notation.
B15: 2 | C15: Each lesson has a Learn tab and an Answers tab with the same layout. Work down the Learn tab and fill the cream boxes.
B17: 3 | C17: A ✓ appears next to each box when your answer is right and a ✗ when it is not. The score sits top right.
B19: 4 | C19: Finished Lesson 4? The full FVM Foundations pack carries on from Lesson 5 (link at the bottom of this tab).
B21: 5 | C21: Keep the Cheat Sheet tab open in another window. It has every boundary type and the exact solutions on one page.
B24: Contents
C26: Lesson | D26: Topic | E26: What you learn | F26: Answers | G26: Progress
B27: L0 | C27: Meshes, cells, centres and faces | D27: Mesh anatomy | E27: Cells, centres, faces, Δx, counting faces in 1D and 2D, notation | F27: Answers | G27: ='L0 Learn'!L3 -> 0 / 16
B28: L1 | C28: What an integral over a cell means | D28: Integrals | E28: dV = dx in 1D, the midpoint rule, ∫ dJ/dx dx = J_e − J_w, conservation | F28: Answers | G28: ='L1 Learn'!L3 -> 0 / 14
B29: L2 | C29: Values and slopes on faces | D29: Face approximations | E29: Central slope, face averages, error halving, boundary half cells | F29: Answers | G29: ='L2 Learn'!L3 -> 0 / 14
B30: L3 | C30: Your first finite volume solution | D30: 1D diffusion | E30: Integrate, approximate, collect: a 2 cell hand solve and 5 cells in Excel | F30: Answers | G30: ='L3 Learn'!L3 -> 0 / 18
B31: L4 | C31: Boundary cells | D31: Boundary conditions | E31: Fixed value (2D rule), known flux, zero gradient, mixed (Robin) | F31: Answers | G31: ='L4 Learn'!L3 -> 0 / 25
B33: Enjoyed it? The full FVM Foundations pack has 6 more worksheets and 8 practice problems. Get it at cfdbyhand.gumroad.com/l/fvm-foundations
B35: Start with How to Use →
B37: This workbook is for your own learning. Please do not share or resell it. Questions, mistakes you spot, or ideas for the next pack: linktr.ee/cfdbyhand
B40: CFD by Hand · Learn CFD one cell at a time · linktr.ee/cfdbyhand

Sheet How to Use
B2: BEFORE YOU START
B3: How to use this pack
B5: 0 Have a pen and paper ready
B7: Do every derivation on paper first. For each problem: sketch the mesh with every centre and face labelled, write the equation, integrate it over ONE cell, replace every face term with centre values, and collect the coefficients. Only then build the table in Excel.
B9: 1 Iterative calculation
B11: From Lesson 3 onwards every cell value is a formula that points at its neighbours, so the formulas refer to each other. Excel needs iterative calculation switched on to solve them (it sweeps the mesh until nothing changes). Switch it on once as below.
B12: W | C12: Windows
C13: File → Options → Formulas. Tick "Enable iterative calculation". Set Maximum Iterations to 1000 and Maximum Change to 0.0001. Press OK.
B15: M | C15: Mac
C16: Excel → Preferences → Calculation. Tick "Use iterative calculation". Set Maximum iterations to 1000 and Maximum change to 0.0001.
B18: The workbook is saved with these settings, but Excel uses the settings of the first workbook you open in a session. If you see a circular reference warning, check this step.
B20: 2 What the colours mean
D22: Your turn. Type a number or a formula, or pick from the drop down list.
C24: 200 | D24: Inputs and given values. Change them to try your own cases.
C26: wall A | D26: Boundary values that sit either side of a row of cells.
C28: ✓ | D28: Your answer matches (within 0.5%).
C30: ✗ | D30: Not quite. Look again at the step above it.
C32: KEY IDEA | D32: The one thing to remember from a section. Coral boxes are mistakes to avoid, dark green boxes tell you what to type in Excel.
B35: 3 Working through a lesson
B37: 1 | C37: Read, then fill
C38: Each section explains one step: the equation, the discretisation, the mesh, then the solve. Read it, then answer the blanks under it before moving on.
B40: 2 | C40: Use formulas, not typed numbers
C41: Wherever you can, type a formula that clicks on the input cells. The checks accept typed numbers, but formulas mean you can change an input and watch the whole problem update. That is the real payoff.
B43: 3 | C43: Stuck?
C44: Open the Answers tab next to it. It has the same layout, so the answer is in the same cell. Click it to see the formula in the formula bar.
B46: 4 | C46: What next
C47: Finished Lesson 4? The full FVM Foundations pack continues with Lessons 5 to 10 (sources, two materials, 2D, any cell shape and convection) and 8 practice problems: cfdbyhand.gumroad.com/l/fvm-foundations
B49: 4 Useful Excel keys
C51: F2 | D51: Edit a cell and see which cells its formula uses, colour coded
C52: F4 | D52: While typing a reference, add $ signs so it stays fixed when you copy the formula
C53: Ctrl + ` | D53: Show every formula on the sheet instead of the values (press again to switch back)
C54: F9 | D54: Recalculate now. With Manual calculation and 1 iteration, each press is one sweep of the solver
C55: Ctrl + Z | D55: If a circular formula goes wrong and fills with huge numbers, undo, or clear the row and retype it
B57: 5 Suggested order
B59: Start with Lesson 0 and work in order: every lesson uses the one before it. When you finish Lesson 4, the full FVM Foundations pack carries on with sources, two materials, 2D, any cell shape and convection, plus 8 practice problems.
B62: CFD by Hand · Learn CFD one cell at a time · linktr.ee/cfdbyhand

Sheet Cheat Sheet
B2: FVM FOUNDATIONS · EVERYTHING ON ONE TAB
B3: Cheat Sheet
B5: The method
B7: Step | C7: What you write | D7: Also | E7: Watch out
B8: Mesh (1D) | C8: Δx = L/n, x_P = (i − ½)Δx | D8: n cells have n + 1 faces | E8: First centre is Δx/2 from the wall
B9: Mesh (2D) | C9: Cells N_x N_y | D9: Faces (N_x+1)N_y + N_x(N_y+1) | E9: Interior faces shared by 2 cells
B10: Integrate | C10: ∫ f dV ≈ f_P ΔV (dV = A dx, A = 1) | D10: Midpoint rule: exact for straight lines | E10: Error per cell ∝ Δx³
B11: Derivatives | C11: ∫ dJ/dx dx = J_e − J_w | D11: 2D/3D: Σ faces J·n A_f | E11: Interior fluxes cancel: conservative
B12: Face slope | C12: (dφ/dx)_e ≈ (φ_E − φ_P)/δx_PE | D12: Error ∝ δx² (second order) | E12: Boundary: (φ_P − φ_A)/(Δx/2)
B13: Face value | C13: φ_e ≈ (φ_P + φ_E)/2 | D13: Uneven: (1 − f)φ_P + f φ_E | E13: Upwind: take the upstream φ
B14: Cell equation | C14: a_P φ_P = Σ a_nb φ_nb + S_u | D14: a_P = Σ a_nb + ΔF − S_p | E14: Keep every a_nb ≥ 0 and S_p ≤ 0
B15: Excel | C15: φ_P = (Σ a_nb φ_nb + S_u)/a_P | D15: Drag across; iterative calculation on | E15: Or [A]{φ} = {b} with MINVERSE
B17: Coefficients and boundaries
B19: Case | C19: a_nb | D19: S_u and S_p | E19: Note
B20: 1D diffusion | C20: a_W = a_E = D = Γ/Δx | D20: none (interior) | E20: Profile is a straight line
B21: Fixed value | C21: a_nb = 0 on that side | D21: S_u = 2Dφ_A, S_p = −2D | E21: The 2 is the half cell
B22: Known flux q in | C22: a_nb = 0 | D22: S_u = +qA, S_p = 0 | E22: Flux out: −qA
B23: Zero gradient | C23: a_nb = 0 | D23: nothing | E23: Insulated, symmetry, outlet
B24: Mixed (Robin) | C24: a_nb = 0 | D24: S_u = h_cφ_∞, S_p = −h_c | E24: h_c = 1/(1/h + (Δx/2)/Γ)
B25: Source | C25: — | D25: S_u += S_C ΔV, S_p += S_P ΔV | E25: S = S_C + S_P φ, S_P ≤ 0
B26: Two materials | C26: D_f = 1/(δx_Pf/Γ_P + δx_fN/Γ_N) | D26: — | E26: Add resistances, never average Γ
B27: 2D rectangles | C27: a_E = ΓΔy/Δx, a_N = ΓΔx/Δy | D27: Wall: 2a_nb φ_wall, −2a_nb | E27: Face length / centre distance
B28: Any cell | C28: a_N = ΓA_f/d_PN (one per face) | D28: Boundary face: ΓA_f/d_Pb | E28: Orthogonal mesh assumed
B29: Central (convection) | C29: a_W = D + F/2, a_E = D − F/2 | D29: Inlet (2D + F)φ_A; outlet (2D − F)φ_B | E29: a_E < 0 when Pe = F/D > 2
B30: Upwind | C30: a_W = D + max(F, 0), a_E = D + max(−F, 0) | D30: Inlet (2D + F)φ_A; outlet 2Dφ_B | E30: Always bounded, first order
B33: CFD by Hand · Learn CFD one cell at a time · linktr.ee/cfdbyhand

Sheet L0 Learn
B2: LESSON 0 · THE ANATOMY OF A MESH (START HERE) · LEARN | L2: PROGRESS
B3: Meshes, cells, centres and faces | L3: =COUNTIF($N$5:$N$203,"✓")&" / 16" -> 0 / 16
B4: Work down the sheet. Fill each cream box; a ✓ appears when it is right. | L4: @CFDbyHand
B6: IN THIS LESSON | C6: By the end of this lesson you will be able to: ▸ say what a mesh, a cell, a cell centre and a face are ▸ work out Δx and every centre and face position of a 1D mesh ▸ count cells and faces in a 2D mesh ▸ read the notation (P, W, E, w, e, Γ, D, a_P ...) used in every lesson
B8: BEFORE YOU START | C8: Nothing. This pack starts from zero and is meant to come BEFORE the Heat Transfer and CFD packs. You need fractions, a little algebra, a pen and paper. About 10 to 20 minutes (a rough guide).
B10: How to use this sheet: read each box from top to bottom like the page of a book. Cream boxes are for you to fill. Type a number, or better a formula that clicks on the blue input cells. A green tick means you are right (within 0.5%), a red cross means look again at the step just above. Stuck? The Answers tab has the same layout, so the answer sits in the same cell there.
B12: 1 | C12: Why split things into cells?
B14: The finite volume method (FVM) is the method inside almost every engineering simulation program that deals with heat, flow or anything that spreads and gets carried around. Its idea fits in one sentence: split the region into small boxes, and make sure that for every box, what goes in equals what comes out (plus anything made inside).
B15: PICTURE IT | C15: Imagine counting people in a building. You cannot follow every person, but you can stand at every door and count who walks through. If you know what crosses every door of every room, you know how the number of people in each room changes. Rooms = cells. Doors = faces. Counting at the doors = fluxes through faces.
B17: New word | E17: What it means
B18: Mesh (grid) | E18: The collection of all the cells covering the region.
B19: Cell / control volume | E19: One small box of the mesh. The two names mean the same thing.
B20: Cell centre (node) | E20: The point in the middle of a cell where its value is stored.
B21: Face | E21: A boundary between two cells, or between a cell and the outside.
B22: φ (phi) | E22: Whatever we are solving for: temperature, concentration, ... one value per cell.
B36: HOW TO READ THIS DIAGRAM | C36: Read it left to right. On the left is the real problem: φ changes smoothly along the bar, so it has a value at every one of infinitely many points. In the middle we chop the bar into 5 cells and keep just ONE value per cell. On the right, each cell gives one balance equation linking it to its neighbours. Five cells, five unknowns, five equations: a computer (or you) can solve that. Everything in this pack is the detail of these three boxes.
B38: A physical law such as "what flows in must flow out" has to hold at every single point of a region. There are infinitely many points, so a computer cannot check them all. The finite volume method does something simpler: it chops the region into a finite number of small boxes called cells (or control volumes), and insists that the law holds for each box as a whole. A few boxes give a rough answer; many small boxes give a good one.
B39: PICTURE IT | C39: Think of a spreadsheet. Each cell of the sheet holds one number. A finite volume mesh is the same idea: each cell of the mesh stores ONE value of the quantity we care about (a temperature, a concentration, anything). We call that quantity φ (phi) so the method works for all of them.
B41: A finite volume mesh stores the unknown φ ______. | N41: =IF(K41="","",IF(TRIM(K41)='L0 Answers'!K41,"✓","✗"))
B57: HOW TO READ THIS DIAGRAM | C57: A cell of the mesh and a cell of a spreadsheet are the same idea. Cell P has four neighbours W, E, N and S; spreadsheet cell C5 has four neighbours B5, D5, C4 and C6. When P’s value is worked out only from its neighbours, the Excel formula in C5 only reads the cells around it. That is why Excel is such a natural tool for the finite volume method.
B60: 2 | C60: A 1D mesh
B62: In 1D (a thin rod, a duct) cells are short pieces of a line. Number them 1, 2, 3 ... from left to right. With n equal cells on a length L each is Δx = L/n wide. Cell i runs from (i − 1)Δx to iΔx and its centre is half way, at (i − ½)Δx.
B63: WORKED EXAMPLE | C63: L = 1, n = 5 → Δx = 0.2. Faces at 0, 0.2, 0.4, 0.6, 0.8, 1.0 (six of them). Centres at 0.1, 0.3, 0.5, 0.7, 0.9 (five of them). Cell 3 runs from 0.4 to 0.6, centre 0.5.
B65: PAUSE AND THINK | C65: Why store values at centres and not at faces? Because the centre is the best single point to represent a whole cell: the value there is (very nearly) the average over the cell. Faces are where things are exchanged.
B81: In 1D a cell is a short piece of a line. Its two ends are its faces and its middle is its centre (or node). Neighbouring cells share a face. The first and last faces sit on the boundary of the domain. With n equal cells on a length L:
B87: Given | F87: Symbol | G87: Value | I87: Unit
B88: Domain length | F88: L | G88: 1
B89: Number of cells | F89: n | G89: 5
B90: Cell width Δx | N90: =IF(K90="","",IF(ISNUMBER(K90),IF(ABS(K90-'L0 Answers'!K90)<=MAX(0.005*ABS('L0 Answers'!K90),0.001),"✓","✗"),"✗"))
B91: Hint: L/n = 1/5.
B93: Number of faces (including the two boundary faces) | N93: =IF(K93="","",IF(ISNUMBER(K93),IF(ABS(K93-'L0 Answers'!K93)<=MAX(0.005*ABS('L0 Answers'!K93),0.001),"✓","✗"),"✗"))
B94: Hint: One more face than cells.
B96: x of the centre of cell 3 | N96: =IF(K96="","",IF(ISNUMBER(K96),IF(ABS(K96-'L0 Answers'!K96)<=MAX(0.005*ABS('L0 Answers'!K96),0.001),"✓","✗"),"✗"))
B97: Hint: Cell 3 runs from 2Δx to 3Δx; take the middle.
B99: x of the face between cells 2 and 3 | N99: =IF(K99="","",IF(ISNUMBER(K99),IF(ABS(K99-'L0 Answers'!K99)<=MAX(0.005*ABS('L0 Answers'!K99),0.001),"✓","✗"),"✗"))
B100: Hint: Two cells to its left, each Δx wide.
B102: Distance from the centre of cell 1 to the left boundary | N102: =IF(K102="","",IF(ISNUMBER(K102),IF(ABS(K102-'L0 Answers'!K102)<=MAX(0.005*ABS('L0 Answers'!K102),0.001),"✓","✗"),"✗"))
B103: Hint: Half a cell.
B105: Distance between the centres of two neighbouring cells | N105: =IF(K105="","",IF(ISNUMBER(K105),IF(ABS(K105-'L0 Answers'!K105)<=MAX(0.005*ABS('L0 Answers'!K105),0.001),"✓","✗"),"✗"))
B107: Now fill a table of the whole mesh. One column per cell. Use formulas with your Δx cell so it updates if you change n.
...

Sheet L0 Answers
B2: LESSON 0 · THE ANATOMY OF A MESH (START HERE) · ANSWERS | L2: PROGRESS
B3: Meshes, cells, centres and faces | L3: =COUNTIF($N$5:$N$203,"✓")&" / 16" -> 16 / 16
B4: Every blank is already filled in on this sheet, with the formula that produces it. Use it to check your Learn sheet. | L4: @CFDbyHand
B6: IN THIS LESSON | C6: By the end of this lesson you will be able to: ▸ say what a mesh, a cell, a cell centre and a face are ▸ work out Δx and every centre and face position of a 1D mesh ▸ count cells and faces in a 2D mesh ▸ read the notation (P, W, E, w, e, Γ, D, a_P ...) used in every lesson
B8: BEFORE YOU START | C8: Nothing. This pack starts from zero and is meant to come BEFORE the Heat Transfer and CFD packs. You need fractions, a little algebra, a pen and paper. About 10 to 20 minutes (a rough guide).
B10: How to use this sheet: read each box from top to bottom like the page of a book. Cream boxes are for you to fill. Type a number, or better a formula that clicks on the blue input cells. A green tick means you are right (within 0.5%), a red cross means look again at the step just above. Stuck? The Answers tab has the same layout, so the answer sits in the same cell there.
B12: 1 | C12: Why split things into cells?
B14: The finite volume method (FVM) is the method inside almost every engineering simulation program that deals with heat, flow or anything that spreads and gets carried around. Its idea fits in one sentence: split the region into small boxes, and make sure that for every box, what goes in equals what comes out (plus anything made inside).
B15: PICTURE IT | C15: Imagine counting people in a building. You cannot follow every person, but you can stand at every door and count who walks through. If you know what crosses every door of every room, you know how the number of people in each room changes. Rooms = cells. Doors = faces. Counting at the doors = fluxes through faces.
B17: New word | E17: What it means
B18: Mesh (grid) | E18: The collection of all the cells covering the region.
B19: Cell / control volume | E19: One small box of the mesh. The two names mean the same thing.
B20: Cell centre (node) | E20: The point in the middle of a cell where its value is stored.
B21: Face | E21: A boundary between two cells, or between a cell and the outside.
B22: φ (phi) | E22: Whatever we are solving for: temperature, concentration, ... one value per cell.
B36: HOW TO READ THIS DIAGRAM | C36: Read it left to right. On the left is the real problem: φ changes smoothly along the bar, so it has a value at every one of infinitely many points. In the middle we chop the bar into 5 cells and keep just ONE value per cell. On the right, each cell gives one balance equation linking it to its neighbours. Five cells, five unknowns, five equations: a computer (or you) can solve that. Everything in this pack is the detail of these three boxes.
B38: A physical law such as "what flows in must flow out" has to hold at every single point of a region. There are infinitely many points, so a computer cannot check them all. The finite volume method does something simpler: it chops the region into a finite number of small boxes called cells (or control volumes), and insists that the law holds for each box as a whole. A few boxes give a rough answer; many small boxes give a good one.
B39: PICTURE IT | C39: Think of a spreadsheet. Each cell of the sheet holds one number. A finite volume mesh is the same idea: each cell of the mesh stores ONE value of the quantity we care about (a temperature, a concentration, anything). We call that quantity φ (phi) so the method works for all of them.
B41: A finite volume mesh stores the unknown φ ______. | K41: once per cell, at its centre | N41: =IF(K41="","",IF(TRIM(K41)='L0 Answers'!K41,"✓","✗")) -> ✓
B57: HOW TO READ THIS DIAGRAM | C57: A cell of the mesh and a cell of a spreadsheet are the same idea. Cell P has four neighbours W, E, N and S; spreadsheet cell C5 has four neighbours B5, D5, C4 and C6. When P’s value is worked out only from its neighbours, the Excel formula in C5 only reads the cells around it. That is why Excel is such a natural tool for the finite volume method.
B60: 2 | C60: A 1D mesh
B62: In 1D (a thin rod, a duct) cells are short pieces of a line. Number them 1, 2, 3 ... from left to right. With n equal cells on a length L each is Δx = L/n wide. Cell i runs from (i − 1)Δx to iΔx and its centre is half way, at (i − ½)Δx.
B63: WORKED EXAMPLE | C63: L = 1, n = 5 → Δx = 0.2. Faces at 0, 0.2, 0.4, 0.6, 0.8, 1.0 (six of them). Centres at 0.1, 0.3, 0.5, 0.7, 0.9 (five of them). Cell 3 runs from 0.4 to 0.6, centre 0.5.
B65: PAUSE AND THINK | C65: Why store values at centres and not at faces? Because the centre is the best single point to represent a whole cell: the value there is (very nearly) the average over the cell. Faces are where things are exchanged.
B81: In 1D a cell is a short piece of a line. Its two ends are its faces and its middle is its centre (or node). Neighbouring cells share a face. The first and last faces sit on the boundary of the domain. With n equal cells on a length L:
B87: Given | F87: Symbol | G87: Value | I87: Unit
B88: Domain length | F88: L | G88: 1
B89: Number of cells | F89: n | G89: 5
B90: Cell width Δx | K90: =$G$88/$G$89 -> 0.2 | N90: =IF(K90="","",IF(ISNUMBER(K90),IF(ABS(K90-'L0 Answers'!K90)<=MAX(0.005*ABS('L0 Answers'!K90),0.001),"✓","✗"),"✗")) -> ✓
B91: Hint: L/n = 1/5.
B93: Number of faces (including the two boundary faces) | K93: =$G$89+1 -> 6 | N93: =IF(K93="","",IF(ISNUMBER(K93),IF(ABS(K93-'L0 Answers'!K93)<=MAX(0.005*ABS('L0 Answers'!K93),0.001),"✓","✗"),"✗")) -> ✓
B94: Hint: One more face than cells.
B96: x of the centre of cell 3 | K96: =2.5*$K$90 -> 0.5 | N96: =IF(K96="","",IF(ISNUMBER(K96),IF(ABS(K96-'L0 Answers'!K96)<=MAX(0.005*ABS('L0 Answers'!K96),0.001),"✓","✗"),"✗")) -> ✓
B97: Hint: Cell 3 runs from 2Δx to 3Δx; take the middle.
B99: x of the face between cells 2 and 3 | K99: =2*$K$90 -> 0.4 | N99: =IF(K99="","",IF(ISNUMBER(K99),IF(ABS(K99-'L0 Answers'!K99)<=MAX(0.005*ABS('L0 Answers'!K99),0.001),"✓","✗"),"✗")) -> ✓
B100: Hint: Two cells to its left, each Δx wide.
B102: Distance from the centre of cell 1 to the left boundary | K102: =$K$90/2 -> 0.1 | N102: =IF(K102="","",IF(ISNUMBER(K102),IF(ABS(K102-'L0 Answers'!K102)<=MAX(0.005*ABS('L0 Answers'!K102),0.001),"✓","✗"),"✗")) -> ✓
B103: Hint: Half a cell.
B105: Distance between the centres of two neighbouring cells | K105: =$K$90 -> 0.2 | N105: =IF(K105="","",IF(ISNUMBER(K105),IF(ABS(K105-'L0 Answers'!K105)<=MAX(0.005*ABS('L0 Answers'!K105),0.001),"✓","✗"),"✗")) -> ✓
B107: Now fill a table of the whole mesh. One column per cell. Use formulas with your Δx cell so it updates if you change n.
...

Sheet L1 Learn
B2: LESSON 1 · INTEGRATING OVER A CONTROL VOLUME · LEARN | L2: PROGRESS
B3: What an integral over a cell means | L3: =COUNTIF($N$5:$N$201,"✓")&" / 14" -> 0 / 14
B4: Work down the sheet. Fill each cream box; a ✓ appears when it is right. | L4: @CFDbyHand
B6: IN THIS LESSON | C6: By the end of this lesson you will be able to: ▸ explain in words what ∫ f dV over a cell means ▸ see why dV = dx in 1D (for a slice of unit area) ▸ use the midpoint rule f_P ΔV and know when it is exact ▸ turn the integral of a derivative into "flux out − flux in" through the faces
B8: BEFORE YOU START | C8: Lesson 0. You do not need to be good at calculus: the only rule used is that integrating a slope gives back the change. About 10 to 20 minutes (a rough guide).
B10: How to use this sheet: read each box from top to bottom like the page of a book. Cream boxes are for you to fill. Type a number, or better a formula that clicks on the blue input cells. A green tick means you are right (within 0.5%), a red cross means look again at the step just above. Stuck? The Answers tab has the same layout, so the answer sits in the same cell there.
B12: 1 | C12: An integral is a sum of tiny pieces
B14: Every finite volume derivation starts with the words "integrate over the control volume". It sounds frightening but it is just adding up. Picture the cell full of tiny pieces. Each piece has a volume dV and some value of f. Multiply and add over every piece: that sum is ∫ f dV.
B15: PICTURE IT | C15: If f is "kg of salt per m³", then f dV is the kg of salt in one tiny piece, and ∫ f dV over the cell is the total salt in the cell. An integral over a cell is always "the total amount of something in the cell".
B17: Why dV = dx in 1D
B18: A 1D problem is really a bar or duct with a cross-section area A. A thin slice of thickness dx has volume A dx. Most problems take a slice of unit area (A = 1, "per square metre"), so dV = dx and the cell volume is simply ΔV = Δx. In 2D with unit depth, dV = dx dy and ΔV = Δx Δy.
B33: HOW TO READ THIS DIAGRAM | C33: Think of the 1D problem as a long bar with cross section A. A thin slice of thickness dx has volume A·dx. If we work "per square metre of cross section" (A = 1), the volume of the slice is just dx. That is all "dV = dx" means. The arrows show what the balance of the slice will be about: something flows in through the left face and out through the right face.
B35: ∫ f dV means: cut the cell into tiny pieces of volume dV, multiply each piece by the value of f there, and add them all up. In 1D the "volume" of a slice of a bar is its area times its length, dV = A dx. With A = 1 (a slice of unit area) that is simply dV = dx, so an integral over a 1D cell is an ordinary integral from its west face to its east face.
B42: IN PLAIN WORDS | C42: The finite volume method keeps one value per cell, so it approximates the integral by "value at the centre × cell volume". This is the midpoint rule. It is exact when f is a straight line and very close otherwise.
B56: IN PLAIN WORDS | C56: The midpoint rule replaces "add up every tiny piece" with "the value in the middle × the size of the cell". It is the natural choice because the FVM stores exactly one value per cell, at its centre.
B59: 2 | C59: Try it: a straight line source
B61: Test the midpoint rule on f = 2 + 3x. Over a straight line the bits above the centre value exactly cancel the bits below it, so "centre value × width" is exact.
B62: WORKED EXAMPLE | C62: Cell 1: x_P = 0.1, Δx = 0.2. Midpoint: f(0.1) × 0.2 = 2.3 × 0.2 = 0.46. Exact: ∫ from 0 to 0.2 of (2 + 3x) dx = 2(0.2) + 1.5(0.2²) = 0.4 + 0.06 = 0.46. Same!
B64: Mesh (5 cells on 0 to 1) | F64: Symbol | G64: Value | I64: Unit
B65: Cell width | F65: Δx | G65: 0.2
B66: Cell | E66: 1 | F66: 2 | G66: 3 | H66: 4 | I66: 5
B67: x_P | E67: 0.1 | F67: 0.3 | G67: 0.5 | H67: 0.7 | I67: 0.9
B68: f(x_P) = 2 + 3x_P | N68: =IF(COUNT(E68:I68)<5,"",IF(SUMPRODUCT(--(ABS(E68:I68-'L1 Answers'!E68:I68)<=0.005*ABS('L1 Answers'!E68:I68)+0.001))=5,"✓","✗"))
B69: midpoint f(x_P)Δx | N69: =IF(COUNT(E69:I69)<5,"",IF(SUMPRODUCT(--(ABS(E69:I69-'L1 Answers'!E69:I69)<=0.005*ABS('L1 Answers'!E69:I69)+0.001))=5,"✓","✗"))
B70: exact 2Δx + 1.5(x_e² − x_w²) | N70: =IF(COUNT(E70:I70)<5,"",IF(SUMPRODUCT(--(ABS(E70:I70-'L1 Answers'!E70:I70)<=0.005*ABS('L1 Answers'!E70:I70)+0.001))=5,"✓","✗"))
B72: For a straight line the midpoint rule is ______. | N72: =IF(K72="","",IF(TRIM(K72)='L1 Answers'!K72,"✓","✗"))
B86: HOW TO READ THIS DIAGRAM | C86: The dashed box is the midpoint rule: centre value × width. Left: for a straight line the bit of curve above the box (red) and the bit below it (blue) are identical triangles, so they cancel and the box is exact. Right: for a curve that bends upwards the red region is bigger than the blue one, so the box slightly underestimates. That small sliver is the error, and it shrinks very fast (like Δx³) as cells get smaller.
B89: 3 | C89: A curved source
B91: Now a curve, f = x². The curve bends upwards, so the centre value is a little below the average and the midpoint rule underestimates slightly. The error per cell is f″Δx³/24, which for x² (f″ = 2) is Δx³/12.
B92: PAUSE AND THINK | C92: Error per cell ∝ Δx³, and there are 1/Δx cells, so the total error ∝ Δx². Halve the cells, quarter the total error. You will see "error ∝ Δx²" again and again: it is called second order accuracy.
B94: Cell | E94: 1 | F94: 2 | G94: 3 | H94: 4 | I94: 5
B95: midpoint x_P² Δx | N95: =IF(COUNT(E95:I95)<5,"",IF(SUMPRODUCT(--(ABS(E95:I95-'L1 Answers'!E95:I95)<=0.005*ABS('L1 Answers'!E95:I95)+0.001))=5,"✓","✗"))
B96: exact (x_e³ − x_w³)/3 | N96: =IF(COUNT(E96:I96)<5,"",IF(SUMPRODUCT(--(ABS(E96:I96-'L1 Answers'!E96:I96)<=0.005*ABS('L1 Answers'!E96:I96)+0.001))=5,"✓","✗"))
B97: error exact − midpoint | N97: =IF(COUNT(E97:I97)<5,"",IF(SUMPRODUCT(--(ABS(E97:I97-'L1 Answers'!E97:I97)<=0.005*ABS('L1 Answers'!E97:I97)+0.001))=5,"✓","✗"))
B99: The error is the same in every cell. It equals Δx³/12: | N99: =IF(K99="","",IF(ISNUMBER(K99),IF(ABS(K99-'L1 Answers'!K99)<=MAX(0.005*ABS('L1 Answers'!K99),0.001),"✓","✗"),"✗"))
B100: Hint: Δx = 0.2, so Δx³/12 = 0.008/12.
B102: Halving Δx would make the error in each cell ______. | N102: =IF(K102="","",IF(TRIM(K102)='L1 Answers'!K102,"✓","✗"))
B103: Hint: The error goes like Δx³: (½)³.
B106: 4 | C106: Integrating a derivative: only the faces survive
B108: This is the most important idea in the whole pack. Equations of physics are written with derivatives: dJ/dx, the rate at which a flux J changes along x. When you integrate a derivative over a cell, the calculus cancels the derivative:
...

Sheet L1 Answers
B2: LESSON 1 · INTEGRATING OVER A CONTROL VOLUME · ANSWERS | L2: PROGRESS
B3: What an integral over a cell means | L3: =COUNTIF($N$5:$N$201,"✓")&" / 14" -> 14 / 14
B4: Every blank is already filled in on this sheet, with the formula that produces it. Use it to check your Learn sheet. | L4: @CFDbyHand
B6: IN THIS LESSON | C6: By the end of this lesson you will be able to: ▸ explain in words what ∫ f dV over a cell means ▸ see why dV = dx in 1D (for a slice of unit area) ▸ use the midpoint rule f_P ΔV and know when it is exact ▸ turn the integral of a derivative into "flux out − flux in" through the faces
B8: BEFORE YOU START | C8: Lesson 0. You do not need to be good at calculus: the only rule used is that integrating a slope gives back the change. About 10 to 20 minutes (a rough guide).
B10: How to use this sheet: read each box from top to bottom like the page of a book. Cream boxes are for you to fill. Type a number, or better a formula that clicks on the blue input cells. A green tick means you are right (within 0.5%), a red cross means look again at the step just above. Stuck? The Answers tab has the same layout, so the answer sits in the same cell there.
B12: 1 | C12: An integral is a sum of tiny pieces
B14: Every finite volume derivation starts with the words "integrate over the control volume". It sounds frightening but it is just adding up. Picture the cell full of tiny pieces. Each piece has a volume dV and some value of f. Multiply and add over every piece: that sum is ∫ f dV.
B15: PICTURE IT | C15: If f is "kg of salt per m³", then f dV is the kg of salt in one tiny piece, and ∫ f dV over the cell is the total salt in the cell. An integral over a cell is always "the total amount of something in the cell".
B17: Why dV = dx in 1D
B18: A 1D problem is really a bar or duct with a cross-section area A. A thin slice of thickness dx has volume A dx. Most problems take a slice of unit area (A = 1, "per square metre"), so dV = dx and the cell volume is simply ΔV = Δx. In 2D with unit depth, dV = dx dy and ΔV = Δx Δy.
B33: HOW TO READ THIS DIAGRAM | C33: Think of the 1D problem as a long bar with cross section A. A thin slice of thickness dx has volume A·dx. If we work "per square metre of cross section" (A = 1), the volume of the slice is just dx. That is all "dV = dx" means. The arrows show what the balance of the slice will be about: something flows in through the left face and out through the right face.
B35: ∫ f dV means: cut the cell into tiny pieces of volume dV, multiply each piece by the value of f there, and add them all up. In 1D the "volume" of a slice of a bar is its area times its length, dV = A dx. With A = 1 (a slice of unit area) that is simply dV = dx, so an integral over a 1D cell is an ordinary integral from its west face to its east face.
B42: IN PLAIN WORDS | C42: The finite volume method keeps one value per cell, so it approximates the integral by "value at the centre × cell volume". This is the midpoint rule. It is exact when f is a straight line and very close otherwise.
B56: IN PLAIN WORDS | C56: The midpoint rule replaces "add up every tiny piece" with "the value in the middle × the size of the cell". It is the natural choice because the FVM stores exactly one value per cell, at its centre.
B59: 2 | C59: Try it: a straight line source
B61: Test the midpoint rule on f = 2 + 3x. Over a straight line the bits above the centre value exactly cancel the bits below it, so "centre value × width" is exact.
B62: WORKED EXAMPLE | C62: Cell 1: x_P = 0.1, Δx = 0.2. Midpoint: f(0.1) × 0.2 = 2.3 × 0.2 = 0.46. Exact: ∫ from 0 to 0.2 of (2 + 3x) dx = 2(0.2) + 1.5(0.2²) = 0.4 + 0.06 = 0.46. Same!
B64: Mesh (5 cells on 0 to 1) | F64: Symbol | G64: Value | I64: Unit
B65: Cell width | F65: Δx | G65: 0.2
B66: Cell | E66: 1 | F66: 2 | G66: 3 | H66: 4 | I66: 5
B67: x_P | E67: 0.1 | F67: 0.3 | G67: 0.5 | H67: 0.7 | I67: 0.9
B68: f(x_P) = 2 + 3x_P | E68: =2+3*E67 -> 2.3 | F68: =2+3*F67 -> 2.9 | G68: =2+3*G67 -> 3.5 | H68: =2+3*H67 -> 4.1 | I68: =2+3*I67 -> 4.7 | N68: =IF(COUNT(E68:I68)<5,"",IF(SUMPRODUCT(--(ABS(E68:I68-'L1 Answers'!E68:I68)<=0.005*ABS('L1 Answers'!E68:I68)+0.001))=5,"✓","✗")) -> ✓
B69: midpoint f(x_P)Δx | E69: =E68*$G$65 -> 0.46 | F69: =F68*$G$65 -> 0.58 | G69: =G68*$G$65 -> 0.7 | H69: =H68*$G$65 -> 0.82 | I69: =I68*$G$65 -> 0.94 | N69: =IF(COUNT(E69:I69)<5,"",IF(SUMPRODUCT(--(ABS(E69:I69-'L1 Answers'!E69:I69)<=0.005*ABS('L1 Answers'!E69:I69)+0.001))=5,"✓","✗")) -> ✓
B70: exact 2Δx + 1.5(x_e² − x_w²) | E70: =2*$G$65+1.5*((E67+$G$65/2)^2-(E67-$G$65/2)^2) -> 0.46 | F70: =2*$G$65+1.5*((F67+$G$65/2)^2-(F67-$G$65/2)^2) -> 0.58 | G70: =2*$G$65+1.5*((G67+$G$65/2)^2-(G67-$G$65/2)^2) -> 0.7 | H70: =2*$G$65+1.5*((H67+$G$65/2)^2-(H67-$G$65/2)^2) -> 0.82 | I70: =2*$G$65+1.5*((I67+$G$65/2)^2-(I67-$G$65/2)^2) -> 0.94 | N70: =IF(COUNT(E70:I70)<5,"",IF(SUMPRODUCT(--(ABS(E70:I70-'L1 Answers'!E70:I70)<=0.005*ABS('L1 Answers'!E70:I70)+0.001))=5,"✓","✗")) -> ✓
B72: For a straight line the midpoint rule is ______. | K72: exact | N72: =IF(K72="","",IF(TRIM(K72)='L1 Answers'!K72,"✓","✗")) -> ✓
B86: HOW TO READ THIS DIAGRAM | C86: The dashed box is the midpoint rule: centre value × width. Left: for a straight line the bit of curve above the box (red) and the bit below it (blue) are identical triangles, so they cancel and the box is exact. Right: for a curve that bends upwards the red region is bigger than the blue one, so the box slightly underestimates. That small sliver is the error, and it shrinks very fast (like Δx³) as cells get smaller.
B89: 3 | C89: A curved source
B91: Now a curve, f = x². The curve bends upwards, so the centre value is a little below the average and the midpoint rule underestimates slightly. The error per cell is f″Δx³/24, which for x² (f″ = 2) is Δx³/12.
B92: PAUSE AND THINK | C92: Error per cell ∝ Δx³, and there are 1/Δx cells, so the total error ∝ Δx². Halve the cells, quarter the total error. You will see "error ∝ Δx²" again and again: it is called second order accuracy.
B94: Cell | E94: 1 | F94: 2 | G94: 3 | H94: 4 | I94: 5
B95: midpoint x_P² Δx | E95: =E67^2*$G$65 -> 0.002 | F95: =F67^2*$G$65 -> 0.018 | G95: =G67^2*$G$65 -> 0.05 | H95: =H67^2*$G$65 -> 0.098 | I95: =I67^2*$G$65 -> 0.162 | N95: =IF(COUNT(E95:I95)<5,"",IF(SUMPRODUCT(--(ABS(E95:I95-'L1 Answers'!E95:I95)<=0.005*ABS('L1 Answers'!E95:I95)+0.001))=5,"✓","✗")) -> ✓
B96: exact (x_e³ − x_w³)/3 | E96: =((E67+$G$65/2)^3-(E67-$G$65/2)^3)/3 -> 0.0026666667 | F96: =((F67+$G$65/2)^3-(F67-$G$65/2)^3)/3 -> 0.018666667 | G96: =((G67+$G$65/2)^3-(G67-$G$65/2)^3)/3 -> 0.050666667 | H96: =((H67+$G$65/2)^3-(H67-$G$65/2)^3)/3 -> 0.098666667 | I96: =((I67+$G$65/2)^3-(I67-$G$65/2)^3)/3 -> 0.16266667 | N96: =IF(COUNT(E96:I96)<5,"",IF(SUMPRODUCT(--(ABS(E96:I96-'L1 Answers'!E96:I96)<=0.005*ABS('L1 Answers'!E96:I96)+0.001))=5,"✓","✗")) -> ✓
B97: error exact − midpoint | E97: =E96-E95 -> 0.00066666667 | F97: =F96-F95 -> 0.00066666667 | G97: =G96-G95 -> 0.00066666667 | H97: =H96-H95 -> 0.00066666667 | I97: =I96-I95 -> 0.00066666667 | N97: =IF(COUNT(E97:I97)<5,"",IF(SUMPRODUCT(--(ABS(E97:I97-'L1 Answers'!E97:I97)<=0.005*ABS('L1 Answers'!E97:I97)+0.001))=5,"✓","✗")) -> ✓
B99: The error is the same in every cell. It equals Δx³/12: | K99: =$G$65^3/12 -> 0.00066666667 | N99: =IF(K99="","",IF(ISNUMBER(K99),IF(ABS(K99-'L1 Answers'!K99)<=MAX(0.005*ABS('L1 Answers'!K99),0.001),"✓","✗"),"✗")) -> ✓
B100: Hint: Δx = 0.2, so Δx³/12 = 0.008/12.
B102: Halving Δx would make the error in each cell ______. | K102: 8 times smaller | N102: =IF(K102="","",IF(TRIM(K102)='L1 Answers'!K102,"✓","✗")) -> ✓
B103: Hint: The error goes like Δx³: (½)³.
B106: 4 | C106: Integrating a derivative: only the faces survive
B108: This is the most important idea in the whole pack. Equations of physics are written with derivatives: dJ/dx, the rate at which a flux J changes along x. When you integrate a derivative over a cell, the calculus cancels the derivative:
...

Sheet L2 Learn
B2: LESSON 2 · APPROXIMATING FACE VALUES AND GRADIENTS · LEARN | L2: PROGRESS
B3: Values and slopes on faces | L3: =COUNTIF($N$5:$N$152,"✓")&" / 14" -> 0 / 14
B4: Work down the sheet. Fill each cream box; a ✓ appears when it is right. | L4: @CFDbyHand
B6: IN THIS LESSON | C6: By the end of this lesson you will be able to: ▸ estimate the slope dφ/dx on a face from two neighbouring centres ▸ estimate the value φ on a face by (weighted) averaging ▸ measure the error and see it fall as δx² ▸ handle the half cell distance at a boundary face
B8: BEFORE YOU START | C8: Lessons 0 and 1. About 10 to 20 minutes (a rough guide).
B10: How to use this sheet: read each box from top to bottom like the page of a book. Cream boxes are for you to fill. Type a number, or better a formula that clicks on the blue input cells. A green tick means you are right (within 0.5%), a red cross means look again at the step just above. Stuck? The Answers tab has the same layout, so the answer sits in the same cell there.
B12: 1 | C12: The problem: we only know centres
B14: After Lesson 1 every equation is written in terms of face fluxes. A diffusion flux needs the SLOPE dφ/dx at a face. A convection flux needs the VALUE φ at a face. We only store φ at centres, so we need approximations, and this lesson checks how good they are on a test function where we know the exact answer.
B28: After integrating, every equation needs things AT THE FACES: the slope dφ/dx (for diffusion) and sometimes the value φ itself (for convection). But φ is only stored at the centres. So we estimate face quantities from the two centres either side:
B34: Let us test them on a function we know exactly, φ(x) = x³, so we can measure the errors.
B36: 2 | C36: Slope at a face
B38: The slope between two points is "rise over run". For a face sitting between P and E, the rise is φ_E − φ_P and the run is the distance between the centres δx_PE.
B39: WORKED EXAMPLE | C39: x_e = 0.4, δx = 0.2: P at 0.3, E at 0.5. φ_P = 0.027, φ_E = 0.125. Slope ≈ (0.125 − 0.027)/0.2 = 0.49. Exact 3x² = 0.48. Error 0.01.
B41: Given | F41: Symbol | G41: Value | I41: Unit
B42: Coarse spacing | F42: δx | G42: 0.2
B43: Fine spacing | F43: δx | G43: 0.1
B44: Face position | F44: x_e | G44: 0.4
B45: φ_P at x = x_e − δx/2 (coarse) | N45: =IF(K45="","",IF(ISNUMBER(K45),IF(ABS(K45-'L2 Answers'!K45)<=MAX(0.005*ABS('L2 Answers'!K45),0.001),"✓","✗"),"✗"))
B46: Hint: (0.4 − 0.1)³.
B48: φ_E at x = x_e + δx/2 (coarse) | N48: =IF(K48="","",IF(ISNUMBER(K48),IF(ABS(K48-'L2 Answers'!K48)<=MAX(0.005*ABS('L2 Answers'!K48),0.001),"✓","✗"),"✗"))
B49: Hint: (0.4 + 0.1)³.
B51: Estimated slope (φ_E − φ_P)/δx | N51: =IF(K51="","",IF(ISNUMBER(K51),IF(ABS(K51-'L2 Answers'!K51)<=MAX(0.005*ABS('L2 Answers'!K51),0.001),"✓","✗"),"✗"))
B52: Hint: Divide by the coarse spacing 0.2.
B54: Exact slope 3x_e² | N54: =IF(K54="","",IF(ISNUMBER(K54),IF(ABS(K54-'L2 Answers'!K54)<=MAX(0.005*ABS('L2 Answers'!K54),0.001),"✓","✗"),"✗"))
B55: Hint: 3 × 0.4².
B57: Error (coarse) | N57: =IF(K57="","",IF(ISNUMBER(K57),IF(ABS(K57-'L2 Answers'!K57)<=MAX(0.005*ABS('L2 Answers'!K57),0.001),"✓","✗"),"✗"))
B59: Estimated slope with the fine spacing | N59: =IF(K59="","",IF(ISNUMBER(K59),IF(ABS(K59-'L2 Answers'!K59)<=MAX(0.005*ABS('L2 Answers'!K59),0.001),"✓","✗"),"✗"))
B61: Error (fine) | N61: =IF(K61="","",IF(ISNUMBER(K61),IF(ABS(K61-'L2 Answers'!K61)<=MAX(0.005*ABS('L2 Answers'!K61),0.001),"✓","✗"),"✗"))
B63: Error ratio coarse/fine | N63: =IF(K63="","",IF(ISNUMBER(K63),IF(ABS(K63-'L2 Answers'!K63)<=MAX(0.005*ABS('L2 Answers'!K63),0.001),"✓","✗"),"✗"))
B64: Hint: Second order: halving δx divides the error by about 4.
B66: IN PLAIN WORDS | C66: Halving the spacing divided the error by 4: the error goes like δx². That is called second order accuracy, and it is why the centre-to-centre slope is the standard choice.
B68: WHY? | C68: Why is this so accurate? The face sits exactly between the two points, so errors on either side cancel (a symmetric or "central" difference). A one-sided slope would only be first order: half the spacing, half the error.
B71: 3 | C71: Value at a face
B73: The face value by averaging is also second order on a uniform mesh. It is the "central differencing" estimate of the face value. Lesson 9 will show it has a problem when the flow is fast, which leads to upwinding.
B74: Face value by averaging (coarse) | N74: =IF(K74="","",IF(ISNUMBER(K74),IF(ABS(K74-'L2 Answers'!K74)<=MAX(0.005*ABS('L2 Answers'!K74),0.001),"✓","✗"),"✗"))
B76: Exact φ at the face | N76: =IF(K76="","",IF(ISNUMBER(K76),IF(ABS(K76-'L2 Answers'!K76)<=MAX(0.005*ABS('L2 Answers'!K76),0.001),"✓","✗"),"✗"))
B78: Error of the average | N78: =IF(K78="","",IF(ISNUMBER(K78),IF(ABS(K78-'L2 Answers'!K78)<=MAX(0.005*ABS('L2 Answers'!K78),0.001),"✓","✗"),"✗"))
B81: 4 | C81: Uneven spacing and boundary faces
B83: On an uneven mesh the face is closer to one centre than the other. Linear interpolation gives more weight to the closer centre. The weight f is simply "how far along from P to E the face is".
B84: WORKED EXAMPLE | C84: P at 0.3, E at 0.6, face at 0.4: f = (0.4 − 0.3)/(0.6 − 0.3) = 1/3. φ_e = (2/3)(10) + (1/3)(40) = 20.
...

Sheet L2 Answers
B2: LESSON 2 · APPROXIMATING FACE VALUES AND GRADIENTS · ANSWERS | L2: PROGRESS
B3: Values and slopes on faces | L3: =COUNTIF($N$5:$N$152,"✓")&" / 14" -> 14 / 14
B4: Every blank is already filled in on this sheet, with the formula that produces it. Use it to check your Learn sheet. | L4: @CFDbyHand
B6: IN THIS LESSON | C6: By the end of this lesson you will be able to: ▸ estimate the slope dφ/dx on a face from two neighbouring centres ▸ estimate the value φ on a face by (weighted) averaging ▸ measure the error and see it fall as δx² ▸ handle the half cell distance at a boundary face
B8: BEFORE YOU START | C8: Lessons 0 and 1. About 10 to 20 minutes (a rough guide).
B10: How to use this sheet: read each box from top to bottom like the page of a book. Cream boxes are for you to fill. Type a number, or better a formula that clicks on the blue input cells. A green tick means you are right (within 0.5%), a red cross means look again at the step just above. Stuck? The Answers tab has the same layout, so the answer sits in the same cell there.
B12: 1 | C12: The problem: we only know centres
B14: After Lesson 1 every equation is written in terms of face fluxes. A diffusion flux needs the SLOPE dφ/dx at a face. A convection flux needs the VALUE φ at a face. We only store φ at centres, so we need approximations, and this lesson checks how good they are on a test function where we know the exact answer.
B28: After integrating, every equation needs things AT THE FACES: the slope dφ/dx (for diffusion) and sometimes the value φ itself (for convection). But φ is only stored at the centres. So we estimate face quantities from the two centres either side:
B34: Let us test them on a function we know exactly, φ(x) = x³, so we can measure the errors.
B36: 2 | C36: Slope at a face
B38: The slope between two points is "rise over run". For a face sitting between P and E, the rise is φ_E − φ_P and the run is the distance between the centres δx_PE.
B39: WORKED EXAMPLE | C39: x_e = 0.4, δx = 0.2: P at 0.3, E at 0.5. φ_P = 0.027, φ_E = 0.125. Slope ≈ (0.125 − 0.027)/0.2 = 0.49. Exact 3x² = 0.48. Error 0.01.
B41: Given | F41: Symbol | G41: Value | I41: Unit
B42: Coarse spacing | F42: δx | G42: 0.2
B43: Fine spacing | F43: δx | G43: 0.1
B44: Face position | F44: x_e | G44: 0.4
B45: φ_P at x = x_e − δx/2 (coarse) | K45: =($G$44-$G$42/2)^3 -> 0.027 | N45: =IF(K45="","",IF(ISNUMBER(K45),IF(ABS(K45-'L2 Answers'!K45)<=MAX(0.005*ABS('L2 Answers'!K45),0.001),"✓","✗"),"✗")) -> ✓
B46: Hint: (0.4 − 0.1)³.
B48: φ_E at x = x_e + δx/2 (coarse) | K48: =($G$44+$G$42/2)^3 -> 0.125 | N48: =IF(K48="","",IF(ISNUMBER(K48),IF(ABS(K48-'L2 Answers'!K48)<=MAX(0.005*ABS('L2 Answers'!K48),0.001),"✓","✗"),"✗")) -> ✓
B49: Hint: (0.4 + 0.1)³.
B51: Estimated slope (φ_E − φ_P)/δx | K51: =($K$48-$K$45)/$G$42 -> 0.49 | N51: =IF(K51="","",IF(ISNUMBER(K51),IF(ABS(K51-'L2 Answers'!K51)<=MAX(0.005*ABS('L2 Answers'!K51),0.001),"✓","✗"),"✗")) -> ✓
B52: Hint: Divide by the coarse spacing 0.2.
B54: Exact slope 3x_e² | K54: =3*$G$44^2 -> 0.48 | N54: =IF(K54="","",IF(ISNUMBER(K54),IF(ABS(K54-'L2 Answers'!K54)<=MAX(0.005*ABS('L2 Answers'!K54),0.001),"✓","✗"),"✗")) -> ✓
B55: Hint: 3 × 0.4².
B57: Error (coarse) | K57: =$K$51-$K$54 -> 0.01 | N57: =IF(K57="","",IF(ISNUMBER(K57),IF(ABS(K57-'L2 Answers'!K57)<=MAX(0.005*ABS('L2 Answers'!K57),0.001),"✓","✗"),"✗")) -> ✓
B59: Estimated slope with the fine spacing | K59: =(($G$44+$G$43/2)^3-($G$44-$G$43/2)^3)/$G$43 -> 0.4825 | N59: =IF(K59="","",IF(ISNUMBER(K59),IF(ABS(K59-'L2 Answers'!K59)<=MAX(0.005*ABS('L2 Answers'!K59),0.001),"✓","✗"),"✗")) -> ✓
B61: Error (fine) | K61: =$K$59-$K$54 -> 0.0025 | N61: =IF(K61="","",IF(ISNUMBER(K61),IF(ABS(K61-'L2 Answers'!K61)<=MAX(0.005*ABS('L2 Answers'!K61),0.001),"✓","✗"),"✗")) -> ✓
B63: Error ratio coarse/fine | K63: =$K$57/$K$61 -> 4 | N63: =IF(K63="","",IF(ISNUMBER(K63),IF(ABS(K63-'L2 Answers'!K63)<=MAX(0.005*ABS('L2 Answers'!K63),0.001),"✓","✗"),"✗")) -> ✓
B64: Hint: Second order: halving δx divides the error by about 4.
B66: IN PLAIN WORDS | C66: Halving the spacing divided the error by 4: the error goes like δx². That is called second order accuracy, and it is why the centre-to-centre slope is the standard choice.
B68: WHY? | C68: Why is this so accurate? The face sits exactly between the two points, so errors on either side cancel (a symmetric or "central" difference). A one-sided slope would only be first order: half the spacing, half the error.
B71: 3 | C71: Value at a face
B73: The face value by averaging is also second order on a uniform mesh. It is the "central differencing" estimate of the face value. Lesson 9 will show it has a problem when the flow is fast, which leads to upwinding.
B74: Face value by averaging (coarse) | K74: =($K$45+$K$48)/2 -> 0.076 | N74: =IF(K74="","",IF(ISNUMBER(K74),IF(ABS(K74-'L2 Answers'!K74)<=MAX(0.005*ABS('L2 Answers'!K74),0.001),"✓","✗"),"✗")) -> ✓
B76: Exact φ at the face | K76: =$G$44^3 -> 0.064 | N76: =IF(K76="","",IF(ISNUMBER(K76),IF(ABS(K76-'L2 Answers'!K76)<=MAX(0.005*ABS('L2 Answers'!K76),0.001),"✓","✗"),"✗")) -> ✓
B78: Error of the average | K78: =$K$74-$K$76 -> 0.012 | N78: =IF(K78="","",IF(ISNUMBER(K78),IF(ABS(K78-'L2 Answers'!K78)<=MAX(0.005*ABS('L2 Answers'!K78),0.001),"✓","✗"),"✗")) -> ✓
B81: 4 | C81: Uneven spacing and boundary faces
B83: On an uneven mesh the face is closer to one centre than the other. Linear interpolation gives more weight to the closer centre. The weight f is simply "how far along from P to E the face is".
B84: WORKED EXAMPLE | C84: P at 0.3, E at 0.6, face at 0.4: f = (0.4 − 0.3)/(0.6 − 0.3) = 1/3. φ_e = (2/3)(10) + (1/3)(40) = 20.
...

Sheet L3 Learn
B2: LESSON 3 · 1D DIFFUSION, INTERIOR CELLS · LEARN | L2: PROGRESS
B3: Your first finite volume solution | L3: =COUNTIF($N$5:$N$232,"✓")&" / 18" -> 0 / 18
B4: Work down the sheet. Fill each cream box; a ✓ appears when it is right. | L4: @CFDbyHand
B6: IN THIS LESSON | C6: By the end of this lesson you will be able to: ▸ integrate the 1D diffusion equation over one cell ▸ replace face slopes with centre values ▸ collect the result into a_P φ_P = a_W φ_W + a_E φ_E ▸ solve 2 cells by hand and 5 cells in Excel
B8: BEFORE YOU START | C8: Lessons 0 to 2. About 10 to 20 minutes (a rough guide).
B10: How to use this sheet: read each box from top to bottom like the page of a book. Cream boxes are for you to fill. Type a number, or better a formula that clicks on the blue input cells. A green tick means you are right (within 0.5%), a red cross means look again at the step just above. Stuck? The Answers tab has the same layout, so the answer sits in the same cell there.
B20: THE RECIPE | C20: Every lesson from here on follows these five steps. Keep this strip in mind: whenever a new effect is added (a boundary, a source, a second dimension, a flow), only step 3 or step 4 changes a little.
B23: 1 | C23: The equation
B25: Diffusion is the spreading of φ from high to low, with a flux J = −Γ dφ/dx (the minus sign: φ flows downhill). In steady state nothing piles up anywhere, so the flux is the same at every point: dJ/dx = 0, which is the equation above.
B26: New word | E26: What it means
B27: Γ (gamma) | E27: Diffusion coefficient: large Γ means φ spreads easily.
B28: Dirichlet boundary | E28: A boundary where the value of φ is fixed.
B29: Discretise | E29: Turn a differential equation into algebraic equations, one per cell.
B31: The simplest useful equation in the method is steady diffusion: φ spreads from high to low with no source. Γ is the diffusion coefficient. (It is heat conduction if φ is temperature, but here we keep it general.)
B37: Given | F37: Symbol | G37: Value | I37: Unit
B38: Domain length | F38: L | G38: 1
B39: Number of cells | F39: n | G39: 5
B40: Diffusion coefficient | F40: Γ | G40: 2
B41: Left boundary value | F41: φ_A | G41: 100
B42: Right boundary value | F42: φ_B | G42: 20
B44: 2 | C44: Step 1: integrate over cell P
B46: Follow Lesson 1 exactly: the thing inside the integral is a derivative (of Γ dφ/dx), so the integral is its value on the east face minus its value on the west face. No approximation yet: this line is exact.
B52: Lesson 1: integrating a derivative leaves only the faces. "Diffusive flux out of the east face minus flux in at the west face is zero".
B54: 3 | C54: Step 2: approximate the faces (Lesson 2)
B56: Now approximate the two slopes with Lesson 2’s centre-to-centre formula. This is the only approximation in the method.
B74: HOW TO READ THIS DIAGRAM | C74: The diffusive flux always runs from high to low. Through the west face it is D_w(φ_W − φ_P): positive if W is higher than P, so φ flows INTO P. Through the east face it is D_e(φ_P − φ_E): positive if P is higher than E, so φ flows OUT of P. In steady state what comes in must go out, which is exactly the cell equation.
B77: 4 | C77: Step 3: collect φ_P
B79: Multiply out and put all φ_P terms on the left. Every interior cell gives the same pattern, with coefficients called a_W, a_E (the neighbours) and a_P (the cell itself).
B80: WORKED EXAMPLE | C80: Γ = 2, Δx = 0.2 → D = 10. 10(φ_E − φ_P) − 10(φ_P − φ_W) = 0 ⇒ 20 φ_P = 10 φ_W + 10 φ_E ⇒ φ_P = (φ_W + φ_E)/2
B82: PAUSE AND THINK | C82: Each cell is simply the average of its neighbours. That is exactly what a straight line looks like, and the exact answer to this problem is a straight line from φ_A to φ_B.
B89: Δx | N89: =IF(K89="","",IF(ISNUMBER(K89),IF(ABS(K89-'L3 Answers'!K89)<=MAX(0.005*ABS('L3 Answers'!K89),0.001),"✓","✗"),"✗"))
B91: D = Γ/Δx | N91: =IF(K91="","",IF(ISNUMBER(K91),IF(ABS(K91-'L3 Answers'!K91)<=MAX(0.005*ABS('L3 Answers'!K91),0.001),"✓","✗"),"✗"))
B92: Hint: 2/0.2.
B94: Interior a_P | N94: =IF(K94="","",IF(ISNUMBER(K94),IF(ABS(K94-'L3 Answers'!K94)<=MAX(0.005*ABS('L3 Answers'!K94),0.001),"✓","✗"),"✗"))
B95: Hint: a_W + a_E = 2D.
B97: An interior φ_P is the ______ of φ_W and φ_E. | N97: =IF(K97="","",IF(TRIM(K97)='L3 Answers'!K97,"✓","✗"))
B110: HOW TO READ THIS DIAGRAM | C110: The same mesh drawn as an electric circuit. Each cell centre is a junction, the value φ is the voltage and the flux is the current. Between two centres the "resistance" is δx/Γ = 1/D. The two end links only span half a cell, so their resistance is halved and their conductance doubled: 2D. You will see this 2D in every boundary cell.
B113: 5 | C113: A two cell problem by hand
B115: With only two cells you can solve the equations by substitution, which shows what "solving the system" really means: every equation must hold at the same time.
B128: HOW TO READ THIS DIAGRAM | C128: The two cell problem drawn to scale. Each centre is half a cell (0.25) from its wall, so those links have conductance 2D = 8. The two centres are a whole cell (0.5) apart, so that link has conductance D = 4. Cell 1 feels the left wall through 8 and its neighbour through 4; cell 2 the same on the other side.
...

Sheet L3 Answers
B2: LESSON 3 · 1D DIFFUSION, INTERIOR CELLS · ANSWERS | L2: PROGRESS
B3: Your first finite volume solution | L3: =COUNTIF($N$5:$N$232,"✓")&" / 18" -> 18 / 18
B4: Every blank is already filled in on this sheet, with the formula that produces it. Use it to check your Learn sheet. | L4: @CFDbyHand
B6: IN THIS LESSON | C6: By the end of this lesson you will be able to: ▸ integrate the 1D diffusion equation over one cell ▸ replace face slopes with centre values ▸ collect the result into a_P φ_P = a_W φ_W + a_E φ_E ▸ solve 2 cells by hand and 5 cells in Excel
B8: BEFORE YOU START | C8: Lessons 0 to 2. About 10 to 20 minutes (a rough guide).
B10: How to use this sheet: read each box from top to bottom like the page of a book. Cream boxes are for you to fill. Type a number, or better a formula that clicks on the blue input cells. A green tick means you are right (within 0.5%), a red cross means look again at the step just above. Stuck? The Answers tab has the same layout, so the answer sits in the same cell there.
B20: THE RECIPE | C20: Every lesson from here on follows these five steps. Keep this strip in mind: whenever a new effect is added (a boundary, a source, a second dimension, a flow), only step 3 or step 4 changes a little.
B23: 1 | C23: The equation
B25: Diffusion is the spreading of φ from high to low, with a flux J = −Γ dφ/dx (the minus sign: φ flows downhill). In steady state nothing piles up anywhere, so the flux is the same at every point: dJ/dx = 0, which is the equation above.
B26: New word | E26: What it means
B27: Γ (gamma) | E27: Diffusion coefficient: large Γ means φ spreads easily.
B28: Dirichlet boundary | E28: A boundary where the value of φ is fixed.
B29: Discretise | E29: Turn a differential equation into algebraic equations, one per cell.
B31: The simplest useful equation in the method is steady diffusion: φ spreads from high to low with no source. Γ is the diffusion coefficient. (It is heat conduction if φ is temperature, but here we keep it general.)
B37: Given | F37: Symbol | G37: Value | I37: Unit
B38: Domain length | F38: L | G38: 1
B39: Number of cells | F39: n | G39: 5
B40: Diffusion coefficient | F40: Γ | G40: 2
B41: Left boundary value | F41: φ_A | G41: 100
B42: Right boundary value | F42: φ_B | G42: 20
B44: 2 | C44: Step 1: integrate over cell P
B46: Follow Lesson 1 exactly: the thing inside the integral is a derivative (of Γ dφ/dx), so the integral is its value on the east face minus its value on the west face. No approximation yet: this line is exact.
B52: Lesson 1: integrating a derivative leaves only the faces. "Diffusive flux out of the east face minus flux in at the west face is zero".
B54: 3 | C54: Step 2: approximate the faces (Lesson 2)
B56: Now approximate the two slopes with Lesson 2’s centre-to-centre formula. This is the only approximation in the method.
B74: HOW TO READ THIS DIAGRAM | C74: The diffusive flux always runs from high to low. Through the west face it is D_w(φ_W − φ_P): positive if W is higher than P, so φ flows INTO P. Through the east face it is D_e(φ_P − φ_E): positive if P is higher than E, so φ flows OUT of P. In steady state what comes in must go out, which is exactly the cell equation.
B77: 4 | C77: Step 3: collect φ_P
B79: Multiply out and put all φ_P terms on the left. Every interior cell gives the same pattern, with coefficients called a_W, a_E (the neighbours) and a_P (the cell itself).
B80: WORKED EXAMPLE | C80: Γ = 2, Δx = 0.2 → D = 10. 10(φ_E − φ_P) − 10(φ_P − φ_W) = 0 ⇒ 20 φ_P = 10 φ_W + 10 φ_E ⇒ φ_P = (φ_W + φ_E)/2
B82: PAUSE AND THINK | C82: Each cell is simply the average of its neighbours. That is exactly what a straight line looks like, and the exact answer to this problem is a straight line from φ_A to φ_B.
B89: Δx | K89: =$G$38/$G$39 -> 0.2 | N89: =IF(K89="","",IF(ISNUMBER(K89),IF(ABS(K89-'L3 Answers'!K89)<=MAX(0.005*ABS('L3 Answers'!K89),0.001),"✓","✗"),"✗")) -> ✓
B91: D = Γ/Δx | K91: =$G$40/$K$89 -> 10 | N91: =IF(K91="","",IF(ISNUMBER(K91),IF(ABS(K91-'L3 Answers'!K91)<=MAX(0.005*ABS('L3 Answers'!K91),0.001),"✓","✗"),"✗")) -> ✓
B92: Hint: 2/0.2.
B94: Interior a_P | K94: =2*$K$91 -> 20 | N94: =IF(K94="","",IF(ISNUMBER(K94),IF(ABS(K94-'L3 Answers'!K94)<=MAX(0.005*ABS('L3 Answers'!K94),0.001),"✓","✗"),"✗")) -> ✓
B95: Hint: a_W + a_E = 2D.
B97: An interior φ_P is the ______ of φ_W and φ_E. | K97: average | N97: =IF(K97="","",IF(TRIM(K97)='L3 Answers'!K97,"✓","✗")) -> ✓
B110: HOW TO READ THIS DIAGRAM | C110: The same mesh drawn as an electric circuit. Each cell centre is a junction, the value φ is the voltage and the flux is the current. Between two centres the "resistance" is δx/Γ = 1/D. The two end links only span half a cell, so their resistance is halved and their conductance doubled: 2D. You will see this 2D in every boundary cell.
B113: 5 | C113: A two cell problem by hand
B115: With only two cells you can solve the equations by substitution, which shows what "solving the system" really means: every equation must hold at the same time.
B128: HOW TO READ THIS DIAGRAM | C128: The two cell problem drawn to scale. Each centre is half a cell (0.25) from its wall, so those links have conductance 2D = 8. The two centres are a whole cell (0.5) apart, so that link has conductance D = 4. Cell 1 feels the left wall through 8 and its neighbour through 4; cell 2 the same on the other side.
...

Sheet L4 Learn
B2: LESSON 4 · FIXED VALUE, FLUX, ZERO GRADIENT AND MIXED BOUNDARIES · LEARN | L2: PROGRESS
B3: Boundary cells | L3: =COUNTIF($N$5:$N$171,"✓")&" / 25" -> 0 / 25
B4: Work down the sheet. Fill each cream box; a ✓ appears when it is right. | L4: @CFDbyHand
B6: IN THIS LESSON | C6: By the end of this lesson you will be able to: ▸ explain why boundary cells need different equations ▸ derive S_u and S_p for a fixed value, a known flux, zero gradient and a mixed boundary ▸ put boundary cells into Excel and check the answers
B8: BEFORE YOU START | C8: Lesson 3. About 10 to 20 minutes (a rough guide). This is one of the most important lessons in the pack.
B10: How to use this sheet: read each box from top to bottom like the page of a book. Cream boxes are for you to fill. Type a number, or better a formula that clicks on the blue input cells. A green tick means you are right (within 0.5%), a red cross means look again at the step just above. Stuck? The Answers tab has the same layout, so the answer sits in the same cell there.
B12: 1 | C12: What is different about a boundary cell?
B14: An interior cell has a neighbour on both sides. A boundary cell has a neighbour on one side and the edge of the domain on the other. There is no φ_W to use. Instead the boundary condition tells us what happens at that face.
B15: IN PLAIN WORDS | C15: Trick used by every FVM code: keep the SAME equation for every cell, a_P φ_P = a_W φ_W + a_E φ_E + S_u with a_P = a_W + a_E − S_p. For a boundary cell set the missing neighbour coefficient to zero and put the boundary’s effect into S_u (a constant) and S_p (multiplies φ_P). Then one Excel formula works everywhere.
B27: A boundary cell has a face on the edge of the domain instead of a neighbour. Write its balance exactly as before, but the boundary face flux comes from the boundary condition instead of a neighbour. To keep one form for every cell we put the boundary’s contribution into two extra numbers: S_u (a fixed amount added) and S_p (an amount × φ_P, always ≤ 0).
B32: 2 | C32: Fixed value (Dirichlet)
B34: WORKED EXAMPLE | C34: Γ = 2, Δx = 0.2 (D = 10), φ_A = 100. West face of cell 1: Γ(φ₁ − 100)/(0.1) = 20(φ₁ − 100). Balance: 10(φ₂ − φ₁) − 20(φ₁ − 100) = 0 ⇒ 30 φ₁ = 10 φ₂ + 2000 ⇒ a_W = 0, a_E = 10, S_u = 2000, S_p = −20, a_P = 30.
